<?xml version="1.0"?>
<robot xmlns:xacro="http://www.ros.org/wiki/xacro">
    <xacro:macro name="wheel" params="prefix parent x y z">
        <link name="${prefix}_wheel_link">
            <visual>
                <origin xyz="0.0 0.0 0.0" rpy="1.5708 0.0 0.0"/>
                <geometry>
                    <cylinder radius="${wheel_radius}" length="${wheel_width}"/>
                </geometry>
                <material name="black"/>
            </visual>
            <collision>
                <origin xyz="0.0 0.0 0.0" rpy="1.5708 0.0 0.0"/>
                <geometry>
                    <cylinder radius="${wheel_radius}" length="${wheel_width}"/>
                </geometry>
            </collision>
            <inertial>
                <origin xyz="0.0 0.0 0.0" rpy="0.0 0.0 0.0"/>
                <mass value="0.5"/>
                <inertia ixx="0.001" ixy="0.0" ixz="0.0" iyy="0.001" iyz="0.0" izz="0.001"/>
            </inertial>
        </link>

        <joint name="${prefix}_wheel_joint" type="continuous">
            <parent link="${parent}"/>
            <child link="${prefix}_wheel_link"/>
            <origin xyz="${x} ${y} ${z}" rpy="0.0 0.0 0.0"/>
            <axis xyz="0.0 1 0.0"/>
        </joint>
    </xacro:macro>
</robot>
